---
layout: post
title: Promise에 대하여
tags:  Js promise
categories:  Js
---    
#### 개요      

최근 Js에 대해 공부하고 있습니다. 개인적으로 프론트에 대해 좋지 않은 인식을 갖고 있었는데, 무지했기때문에 그런 인식을 갖고 있던것 같습니다.    

> Js를 공부 할 수록 꽤 재밋는 분야라고 생각하고 있습니다.    

2016년도 쯤, service Worker를 이용한 push 알람을 구현하려고 한적이 있습니다. 대부분의  예제는 promise로 구현됐었고, Js를 공부하지 않았던 저는 결국 push기능을 포기했습니다. 때문에 Js 공부를 시작할 무렴 promise를 알고싶다는 생각이 들었습니다.   

그래서 한번 정리해봤습니다.     

#### Promise    



Javascript를 사용하다보면 비동기로 서버측에 정보를 요청하는 '$.ajax'를 자주 볼 수 있습니다. 

	$.ajax({
		  method: "GET",
		  url: "/",
		  success : function(data) {
        	alert("success!");
    	}
	});

요청을 보내고, 성공시 success message를 보여주는 로직입니다. 단순히 1~2개의 요청을 보낸다고 하면 큰 문제는 없습니다. 다만, 다수의 비동기에서 선/후 관계가 생긴다면 콜백지옥을 볼 수 있습니다. 
 
	//선행
	$.ajax({
		  method: "GET",
		  url: "/",
		  success : function(data) {
	    	alert("success!");
			// 후행
			$.ajax({
				  method: "GET",
				  url: "/",
				  success : function(data) {
		    		alert("success!");
				}
            })
		}
    }); 

> 실제로 이렇게 쓴 코드는 본적이 없지만 ...     

위 방식은 콜백지옥을 보일 뿐더러, 코드를 읽기 어렵습니다.     
기존 ajax방식에는 또 하나의 단점이 존재합니다. 바로 예외처리에 대한 부분이죠.      

> ajax의 success 부분에서 throw를 던져도 특별한 처리를 할 수 없습니다.  

	$.ajax({
		  method: "GET",
		  url: "/",
		success : function(data) {
        	alert("success!");
    		throw "에러";
			alert("?");
		},
		error  : function(){
    		alert("???");
		}
	});   

위 코드를 작성했던 의도는 throw를 통해 error의 코드를 실행하는 것입니다. 하지만, 의도한 바와는 달리 작동하는데, 그 이유는 error은 예외 처리를 하는 인자가 아닌, 비동기 통신이 실패할때 실행되는 코드입니다. 기존 ajax객체에선 예외처리를 지원하지 않기 때문에, 따로 코드를 작성해서 처리를 진행해야합니다.     

> 이러한 문제때문에 등장한 것이 promise 입니다.         

관심이 있으시다면, 
[ajax 예외처리에 대하여](https://blog.coderifleman.com/2014/11/15/javascript-and-async-error/) 글을 보시면 될것 같습니다.    

### Promise 개념         

기존 비동기 방식은 예외처리와 콜백지옥에 대한 단점이 존재했습니다. 이를 해결하기위해 등장한 패턴(?)이 Promise를 사용한 패턴 입니다.      

> Promise란 비동기 처리를 **추상화**한 객체로, 이를 이용해 비동기를 처리 할 수 있습니다.    

정말 사전적인 의미이지만 중요한 부분은 **추상화** 라는 단어 입니다.      
추상화를 했다는 것은, Promise를 사용하는 모든 객체의 틀이 잡혀있다는 의미로 비동기 처리를 패턴화 할 수 있다는 장점을 갖고 있습니다.       

> 즉, promise를 재정의 하더라도, 정해진 함수만 사용할 수 있습니다.      


### Promise 사용      

	var promise = new Promise(function(resolve, reject){});    

promise는 위와같이 사용 할 수 있습니다.  resolve 는 성공했을 때, reject는 실패했을 때 실행되는 함수입니다. 

	var promise = new Promise(function(resolve, reject){
		if(true){
			resolve("성공");
		}
		reject("실패");
	});    

	promise.then(function(data){ console.log(data)});


> 출력 결과 > 성공      

성공시 resolve의 함수의 인자를 then()의 인자로 넘겨주게 됩니다. 물론 실패도 마찬가지 방식으로 동작합니다.    
   
	promise.then(onFulfilled, onRejected); 

then 함수를 이용하면, 성공시 onFulfilled, 실패시 onRejected를 수행하게 됩니다.   
이때 promise에서 정의한 resolve 와 reject 의 인자를 넘겨주어 처리 할 수 있습니다.    


**추가적으로**

Promise를 직접 new로 생성하는 방식 이외에도, 
	
	var promise = Promise.resolve();    

이와같이 promise를 생성할 수 있습니다.     

다만 위경우, 상태를 fulfilled로 생성하여 Promise를 반환합니다. 
즉, Promise.resolve()로 생성한 객체는 then함수의 첫번째 인자가 실행됩니다.    
> 성공한 상태의 객체를 반환하므로,  then함수의 첫번째 인자가 실행됩니다.     

[링크](http://han41858.tistory.com/11)             

    
#### 상태     

promise는 4가지중 한가지의 상태를 갖습니다.      

**pending**   막 초기화된 상태   
**fulfilled**   성공한 상태       
**rejected**    실패한 상태     
**settled**   완료한 상태      

promise는 비동기 이므로, 해당 객체가 처리 됬는지를 알기 위해 상태를 이용합니다.  

resolve와 reject 함수가 호출되기 전 상태가 pending입니다.     
비동기 작업 이후, 성공시 resolve를, 실패시 reject를 호출 합니다. 

> 추가적으로 fulfilled/rejected 상태에서 pending으로는 상태가 변하지 않습니다.       
> fulfilled > rejected , rejected > fulfilled 으로도 상태를 변경 할 수 없습니다.     


### 예외 처리    

Promise에서는 예외처리를 지원하는데, 만약 throw가 발생한다면 다음과 같이 코드를 작성하면 됩니다.   

	var promise = new Promise(function(resolve,reject){
		if(true){
			resolve(function(){
				alert("test");
				throw "error";
			});
		}
		reject("error");
	});
	
	promise.then(function(success){
		success();
	}, function(fail){
		fail();
	}).catch(function(message){
		console.log(message);
	});   


해당 함수는 resolve의 인자로 함수를 넘겨주는데, 그 안에서 throw를 발생시킵니다.  이때 기존 ajax의 success 부분이라면, error 코드로 넘어가는 것이 아닌, 함수 자체를 끝내버립니다. 
promise는 ajax와는 달리,  throw가 발생하면 catch로 인자를 넘겨 처리 할 수 있습니다. 

즉, Promise는 throw 처리를 지원합니다.    
 
> 출력결과 : alret("texst") - > console :: error     


### CallBack 지옥 해결방안       

Promise의 깔끔한 콜백을 보여주기위해 조금 극단적인(?) 예시를 만들어 봤습니다.   
check1 , check2 , check3 함수는 숫자를 받아, 0이 아니면 정해진 값을 곱하는 promise를 return 합니다.    

	var check1 = function(data){
		return new Promise(function(resolve,reject){	
			if(data !==0){
				resolve(data*5);
			}
			reject(0);
		});
	};
	


	var check2 = function(data){
		return new Promise(function(resolve,reject){	
			if(data !==0){
				//throw "Exception";
				resolve(data*6);
			}
			reject(0);
		});
	};


	var check3 = function(data){
		return new Promise(function(resolve,reject){	
			if(data !==0){
				resolve(data*7);
			}
			reject(0);
		});
	};

만들어둔 check를 이용하여 특정 값 * 5 * 6 * 7 의 값을 보여주는 로직을 구현했습니다.   
물론 이때의 전제조건은 선행 작업이 수행된 후, 후행 작업이 실행되야 한다는 점 입니다. 

	check1(4).then(function(data){
		return check2(data);
	}).then(function(data){
		return check3(data);
	}).then(function(data){
		console.log(data);
	});      

check1 의 작업이 완료되면, 반환된 data를 check2에게 넘겨 해당 promise 객체를 리턴하는 방식 입니다.  결국 then 함수에서 promise 객체를 리턴함으로 끝없이 chaining이 가능하게 되고, 위와같이 사용 가능합니다.    
이때의 장점은 콜백지옥이 아닌, 모든 함수를 1 depth로 처리할 수 있다는 점 입니다.   

> 보기 편합니다 !  

### 삽질의 시작    

위의 예제만으로 넘어가기엔 궁금한 점이 생겨, setTimeout을 사용해 봤습니다.    
위 예제에 단순히 settimeout만을 추가하여 1초후 결과를 반환하는 코드를 작성했습니다.    
 
> 추가적으로, 입력받은 값에 *2 를 하는 함수로 변경하였습니다.  

 
	var check1 = function(data){
		return  new Promise(function(resolve,reject){	
			if(data !==0){
				setTimeout(function() {
	            	resolve(data*2);
	        	}, 2000);
			}
			reject("실패");			
		});
	};
	
	
	
	var check2 = function(data){
		return new Promise(function(resolve,reject){	
			if(data !==0){
				setTimeout(function() {
	            	resolve(data*2);
	        	}, 2000);
			}
			reject("실패");
		});
	};
	
	
	var check3 = function(data){
		return new Promise(function(resolve,reject){	
			if(data !==0){
				setTimeout(function() {
	            	resolve(data*2);
	        	}, 2000);
			}
			reject("실패");
		});
	};

위 코드가 **구현부**, 아래 코드가 **실행부** 입니다.     

	check1(4).then(function(data){
		return check2(data);
	}).then(function(data){
		return check3(data);
	}).then(function(data){
		console.log(data);
	});    

어떤 결과가 나올까요 ?       

Title이 삽질의 시작이므로.. 결과는 역시 예상과 달랐습니다. 결과에 좌절한 저는 구글링을 하다가 맥주를 마시러 갔습니다.......       

> 그리고 그 다음날인 오늘 삽질을 끝낼 수 있었습니다.      

위 코드의 출력 결과는 다음과 같습니다.   

	Uncaught (in promise) 실패    


**삽질 제 1 장**     

실행 결과가 왜 다를까 생각 하던 중, 첫번째 생각은 이랬습니다. 

	then() 함수의 onRejected 부분을 작성하지 않았기 떄문이다 !    

그 후 당장, then() 부분의 onRejected 인자를 추가하여 console.log()를 찍어봤습니다.
		
	.then(success,function(error){		
		console.log(error);
	});    

'실패'라는 문장이 console 로 찍히더군요.   

onRejected의 문제는 아니였던걸로 ....

> 물론 문제가 없더라도  onRejected부분은 구현해야 된다고 생각합니다.     
> 예외처리와 마찬가지로, 실패/예외시 처리를 진행해야 되기 때문입니다.      

**삽질 제 2 장**      

두번째 생각은 다음과 같았습니다.   

	setTimeout()이 잘못되었다.       

setTimeout은 window 객체이기 때문에 window.setTimeout()을 사용해야 된다 라는 결론에 도달했고, test를 진행함과 동시에  제 정신이 아님을 깨달았습니다....   

> global object인 window에 있는 함수들은 함수 명만으로도 호출이 가능합니다.      
 
관련 글 :: [setTimeout 과 window.setTimeout](https://stackoverflow.com/questions/20420429/what-the-difference-between-window-settimeout-and-settimeout)   

이럴때 생각나는 말이 있습니다.   

> 컴퓨터는 잘못이 없습니다. 있다면, 제가 잘못입니다 ...      


**삽질 제 3 장**     

Promise가 문제다 ! 

	promise에서 setTimeout을 하면 1초후에 실행되고 비동기를 지원하지 않는다 !     

> 예.. 정신이 나갔었나 봅니다.     

앞서 말한 promise의 개념은 다음과 같습니다. 

Promise란 비동기 처리를 추상화한 객체로, 이를 이용해 **비동기를 처리 할 수 있습니다.**   

여기까지 삽질을 하다가 맥주를 마시러 갔고, 오늘 삽을 부러뜨릴 수 있었습니다.            


**삽질 마지막 장**  

사실 위 결과는 Promise나 setTime 아웃의 문제가 아닌, Js에 대한 이해의 부족으로 나온 결과 입니다.    

> 언어는 잘못이 없습니다 ...       

 check 함수를 다시 한번 자세히 보겠습니다.   

	var check1 = function(data){
		return  new Promise(function(resolve,reject){	
			if(data !==0){
				setTimeout(function() {
	            	resolve(data*2);
	        	}, 2000);
			}
			reject("실패");			
		});
	};    


자세히 봐야할 부분은 Promise의 인자로 넘어가는 함수부분입니다.      


		function(resolve,reject){	
			if(data !==0){
				setTimeout(function() {
	            	resolve(data*2);
	        	}, 2000);
			}
			reject("실패");			
		}     

만약 data가 0이 아니면 , 2초후 *2를 한 값을 onFulfilled의 인자로 넘기는 코드입니다. 여기서 무슨 문제가 있는지 예상되시나요 ?       

> 아시는분은 Event Loop를 잘 알고 계십니다 !       

간단하게 설정하자면, setTimeout같은 비동기 함수들은 바로 실행되는것이 아닌, Queue가 비어있을 때, 마지막으로(?) 실행 됩니다. 즉 resolve에서 해당 함수가 끝나는 것을 의도했지만, setTimeout이 즉시 실행되지 않으므로, if문을 나와 reject까지 읽어, 결국엔 reject를 뱉게 됩니다.    

Event Loop 만의 문제뿐만 아닌, 제 잘못된 코딩스타일 또한 에러의 원인이 되었습니다.     

> resolve()를 일종의 return 문이라고 생각했기에, else를 안써도 된다고 생각해서 위같이 작성했는데, 잘못된 생각 이였습니다.      

즉, 위 함수를 다음과 같이 수정하면 정상적으로 작동하게 됩니다.     

		function(resolve,reject){	
			if(data !==0){
				setTimeout(function() {
	            	resolve(data*2);
	        	}, 2000);
			}else{
				reject("실패");			
			}
		}     

> Event Loop에 대한 글을 따로 정리했습니다.     

[EventLoop](/js/2017/08/06/EventLoop/)에 대하여.        

#### 정리      

Promise는 콜백지옥을 완화 시킬 수 있을 뿐더러, catch를 통해 예외 처리또한 가능합니다. 
나아가 promise를 반환하는 객체들을 이용하면 쉽게 chaining을 사용 할 수 있습니다. 

> 모두들 Promise 쓰세요 .. !          



참조      

[[JavaScript] 바보들을 위한 Promise 강의 - 도대체 Promise는 어떻게 쓰는거야?](http://programmingsummaries.tistory.com/325)      

08-03 ~ 05
lusiue@gmail.com       

사실 아직은 써봐라 이러면 못쓸거 같긴합니다...  

